Workbook

Sheet Risicoprofiel bepalen - bron
D1: RISICOPROFIEL BEPALEN PARTICULIER
A3: Naam : | F3: Punten | H3: Punten
A4: Adres : | H4: te behalen
A5: Woonplaats :
B7: 1 | D7: Wat is uw beleggingsdoelstelling ?
U8: 1 | V8: =CONCATENATE(Y8,Z8) -> 100RM zeer defensieve belegger | Y8: 100RM | Z8: zeer defensieve belegger
B9: 1 | C9: A | D9: Vermogensgroei of vermogensbehoud met een bepaald doelvermogen | E9: X | F9: =IF($E9="X",+$H9,0) -> 2 | H9: 2 | T9: X | U9: 2 | V9: =CONCATENATE(Y9,Z9) -> 100RM zeer defensieve belegger | W9: 3 | Y9: 100RM | Z9: zeer defensieve belegger
B10: 1 | C10: B | D10: Vermogensgroei of vermogensbehoud zonder een bepaald doelvermogen | E10: 0 | F10: =IF($E10="X",+$H10,0) -> 0 | H10: 3 | T10: 0 | U10: 3 | V10: =CONCATENATE(Y10,Z10) -> 20RD80RM Defensieve belegger | Y10: 20RD80RM | Z10: Defensieve belegger
B11: 1 | C11: C | D11: Jaarlijkse aanvulling op het huidige inkomen | E11: 0 | F11: =IF($E11="X",+$H11,0) -> 0 | H11: 0 | U11: 4 | V11: =CONCATENATE(Y11,Z11) -> 20RD80RM Defensieve belegger | Y11: 20RD80RM | Z11: Defensieve belegger
B12: 1 | C12: D | D12: Financiering van een toekomstige uitgave, bv de studie van kinderen, of eerder stoppen met werken | E12: 0 | F12: =IF($E12="X",+$H12,0) -> 0 | H12: 1 | U12: 5 | V12: =CONCATENATE(Y12,Z12) -> 20RD80RM Defensieve belegger | Y12: 20RD80RM | Z12: Defensieve belegger
B14: 2 | D14: Bent U van plan tussentijds vermogen aan uw beleggingsportefeuille te onttrekken of juist vervolgstortingen te doen ? | U14: 6 | V14: =CONCATENATE(Y14,Z14) -> 20RD80RM Defensieve belegger | Y14: 20RD80RM | Z14: Defensieve belegger
D15: Ik ben van plan:
B17: 2 | C17: A | D17: Periodiek te onttrekken | E17: 0 | F17: =IF($E17="X",+$H17,0) -> 0 | H17: 0 | U17: 7 | V17: =CONCATENATE(Y17,Z17) -> 20RD80RM Defensieve belegger | W17: 6 | Y17: 20RD80RM | Z17: Defensieve belegger
B18: 2 | C18: B | D18: Periodiek bij te storten | E18: 0 | F18: =IF($E18="X",+$H18,0) -> 0 | H18: 6 | U18: 8 | V18: =CONCATENATE(Y18,Z18) -> 20RD80RM Defensieve belegger | Y18: 20RD80RM | Z18: Defensieve belegger
B19: 2 | C19: C | D19: Incidenteel te onttrekken | E19: X | F19: =IF($E19="X",+$H19,0) -> 2 | H19: 2 | U19: 9 | V19: =CONCATENATE(Y19,Z19) -> 30RD70RM Gematigd Defensieve belegger | Y19: 30RD70RM | Z19: Gematigd Defensieve belegger
B20: 2 | C20: D | D20: Incidenteel bij te storten | E20: 0 | F20: =IF($E20="X",+$H20,0) -> 0 | H20: 4 | U20: 10 | V20: =CONCATENATE(Y20,Z20) -> 30RD70RM Gematigd Defensieve belegger | Y20: 30RD70RM | Z20: Gematigd Defensieve belegger
B21: 2 | C21: E | D21: Geen of een combinatie van bovenstaande mogelijkheden | E21: 0 | F21: =IF($E21="X",+$H21,0) -> 0 | H21: 3 | U21: 11 | V21: =CONCATENATE(Y21,Z21) -> 30RD70RM Gematigd Defensieve belegger | Y21: 30RD70RM | Z21: Gematigd Defensieve belegger
B23: 3 | D23: Welke gevolgen heeft het niet halen van uw beleggingsdoelstellingen ? | U23: 12 | V23: =CONCATENATE(Y23,Z23) -> 30RD70RM Gematigd Defensieve belegger | W23: 4 | Y23: 30RD70RM | Z23: Gematigd Defensieve belegger
B25: 3 | C25: A | D25: Dit heeft noch financiële, noch emotionele gevolgen | E25: 0 | F25: =IF($E25="X",+$H25,0) -> 0 | H25: 3 | U25: 13 | V25: =CONCATENATE(Y25,Z25) -> 40RD60RM Neutrale Defensieve belegger | Y25: 40RD60RM | Z25: Neutrale Defensieve belegger
B26: 3 | C26: B | D26: Dit zou grote financiële en emotionele consequenties hebben | E26: 0 | F26: =IF($E26="X",+$H26,0) -> 0 | H26: 0 | U26: 14 | V26: =CONCATENATE(Y26,Z26) -> 40RD60RM Neutrale Defensieve belegger | Y26: 40RD60RM | Z26: Neutrale Defensieve belegger
B27: 3 | C27: C | D27: Ik zou teleurgesteld zijn, maar het zou nauwelijks invloed hebben op mijn levenspeil | E27: X | F27: =IF($E27="X",+$H27,0) -> 2 | H27: 2 | U27: 15 | V27: =CONCATENATE(Y27,Z27) -> 40RD60RM Neutrale Defensieve belegger | Y27: 40RD60RM | Z27: Neutrale Defensieve belegger
B28: 3 | C28: D | D28: Ik zou mijn levensstandaard moeten aanpassen | E28: 0 | F28: =IF($E28="X",+$H28,0) -> 0 | H28: 1 | U28: 16 | V28: =CONCATENATE(Y28,Z28) -> 40RD60RM Neutrale Defensieve belegger | Y28: 40RD60RM | Z28: Neutrale Defensieve belegger
B29: 3 | C29: E | D29: Dit zou gevolgen hebben voor………………………. | E29: 0 | F29: =IF($E29="X",+$H29,0) -> 0 | H29: 1
B31: 4 | D31: Welk deel van uw vrij beschikbare vermogen (exclusief de eigen woning) is of wordt belegd op de rekening die wordt beheerd door B.A. van Doorn Comp ? | U31: 17 | V31: =CONCATENATE(Y31,Z31) -> 40RD60RM Neutrale Defensieve belegger | Y31: 40RD60RM | Z31: Neutrale Defensieve belegger
B33: 4 | C33: A | D33: Meer dan 75% | E33: X | F33: =IF($E33="X",+$H33,0) -> 0 | H33: 0 | U33: 18 | V33: =CONCATENATE(Y33,Z33) -> 40RD60RM Neutrale Defensieve belegger | W33: 6 | Y33: 40RD60RM | Z33: Neutrale Defensieve belegger
B34: 4 | C34: B | D34: 50% - 75% | E34: 0 | F34: =IF($E34="X",+$H34,0) -> 0 | H34: 1 | U34: 19 | V34: =CONCATENATE(Y34,Z34) -> 50RD50RM Neutrale belegger | Y34: 50RD50RM | Z34: Neutrale belegger
B35: 4 | C35: C | D35: 25% - 50% | E35: 0 | F35: =IF($E35="X",+$H35,0) -> 0 | H35: 2 | U35: 20 | V35: =CONCATENATE(Y35,Z35) -> 50RD50RM Neutrale belegger | Y35: 50RD50RM | Z35: Neutrale belegger
B36: 4 | C36: D | D36: Minder dan 25% | E36: 0 | F36: =IF($E36="X",+$H36,0) -> 0 | H36: 3 | U36: 21 | V36: =CONCATENATE(Y36,Z36) -> 50RD50RM Neutrale belegger | Y36: 50RD50RM | Z36: Neutrale belegger
B38: 5 | D38: Uw huidige inkomen (uit loon, pensioen onderneming ed) is :
U39: 22 | V39: =CONCATENATE(Y39,Z39) -> 50RD50RM Neutrale belegger | Y39: 50RD50RM | Z39: Neutrale belegger
B40: 5 | C40: A | D40: Onvoldoende om uw vaste lasten en kosten van levensonderhoud te betalen. U komt maandelijks geld tekort. | E40: 0 | F40: =IF($E40="X",+$H40,0) -> 0 | H40: 0 | U40: 23 | V40: =CONCATENATE(Y40,Z40) -> 50RD50RM Neutrale belegger | W40: 8 | Y40: 50RD50RM | Z40: Neutrale belegger
B41: 5 | C41: B | D41: Soms voldoende, soms onvoldoende. Aan het eind van het jaar komt u ongeveer uit. | E41: X | F41: =IF($E41="X",+$H41,0) -> 2 | H41: 2 | U41: 24 | V41: =CONCATENATE(Y41,Z41) -> 50RD50RM Neutrale belegger | Y41: 50RD50RM | Z41: Neutrale belegger
B42: 5 | C42: C | D42: Voldoende om uw vaste lasten en kosten van levensonderhoud te betalen. U kunt maandelijks een bedrag opzij zetten. | E42: 0 | F42: =IF($E42="X",+$H42,0) -> 0 | H42: 4 | U42: 25 | V42: =CONCATENATE(Y42,Z42) -> 50RD50RM Neutrale belegger | Y42: 50RD50RM | Z42: Neutrale belegger
B43: 5 | C43: D | D43: Ruim voldoende om uw vaste lasten en kosten van levensonderhoud te betalen. | E43: 0 | F43: =IF($E43="X",+$H43,0) -> 0 | H43: 6 | U43: 26 | V43: =CONCATENATE(Y43,Z43) -> 50RD50RM Neutrale belegger | Y43: 50RD50RM | Z43: Neutrale belegger
B44: 5 | C44: E | D44: Voldoende om maandelijks een aanzienlijk bedrag opzij te zetten. | E44: 0 | F44: =IF($E44="X",+$H44,0) -> 0 | H44: 8 | U44: 27 | V44: =CONCATENATE(Y44,Z44) -> 60RD40RM Neutrale offensiefe belegger | Y44: 60RD40RM | Z44: Neutrale offensiefe belegger
B47: 6 | D47: Welke kansverdeling spreekt u het meest aan voor het door U te beleggen vermogen ? | U47: 28 | V47: =CONCATENATE(Y47,Z47) -> 60RD40RM Neutrale offensiefe belegger | Y47: 60RD40RM | Z47: Neutrale offensiefe belegger
B49: 6 | C49: A | D49: Een gemiddeld rendement van 6%, maar in een slecht jaar kan ik uitkomen op min 29% | E49: 0 | F49: =IF($E49="X",+$H49,0) -> 0 | H49: 3 | U49: 29 | V49: =CONCATENATE(Y49,Z49) -> 60RD40RM Neutrale offensiefe belegger | Y49: 60RD40RM | Z49: Neutrale offensiefe belegger
B50: 6 | C50: B | D50: Een gemiddeld rendement van 3%, maar in een slecht jaar kan ik uitkomen op min 14% | E50: X | F50: =IF($E50="X",+$H50,0) -> 2 | H50: 2 | U50: 30 | V50: =CONCATENATE(Y50,Z50) -> 60RD40RM Neutrale offensiefe belegger | Y50: 60RD40RM | Z50: Neutrale offensiefe belegger
B51: 6 | C51: C | D51: Een gemiddeld rendement van 1%, maar in een slecht jaar kan ik uitkomen op min 8% | E51: 0 | F51: =IF($E51="X",+$H51,0) -> 0 | H51: 1 | U51: 31 | V51: =CONCATENATE(Y51,Z51) -> 60RD40RM Neutrale offensiefe belegger | W51: 6 | Y51: 60RD40RM | Z51: Neutrale offensiefe belegger
B52: 6 | C52: D | D52: Een jaarlijks rendement gelijk aan de spaarrente, ook in een slecht jaar. | E52: 0 | F52: =IF($E52="X",+$H52,0) -> 0 | H52: 0 | U52: 32 | V52: =CONCATENATE(Y52,Z52) -> 60RD40RM Neutrale offensiefe belegger | Y52: 60RD40RM | Z52: Neutrale offensiefe belegger
...

Sheet vragen org
A1: nummer | B1: vraag | C1: onderwerp | D1: antwoord_aanhef
A2: 1 | B2: Wat is uw beleggingsdoelstelling? | C2: beleggingsdoelstelling | D2: Mijn beleggingsdoelstelling is:
A3: 2 | B3: Bent U van plan tussentijds vermogen aan uw beleggingsportefeuille te onttrekken of juist vervolgstortingen te doen? | C3: bijstortingen | D3: Ik ben van plan:
A4: 3 | B4: Welke gevolgen heeft het niet halen van uw beleggingsdoelstellingen? | C4: gevolgen | D4: Het niet halen van doelstellingen:
A5: 4 | B5: Welk deel van uw vrij beschikbare vermogen (exclusief de eigen woning) is of wordt belegd op de rekening die wordt beheerd door B.A. van Doorn Comp? | C5: deel | D5: Het deel van mijn vermogen dat wordt beheerd door B.A. van Doorn Comp is:
A6: 5 | B6: Uw huidige inkomen (uit loon, pensioen onderneming ed) is : | C6: inkomen | D6: Mijn huidige inkomen is:
A7: 6 | B7: Welke kansverdeling spreekt u het meest aan voor het door U te beleggen vermogen? | C7: kansverdeling | D7: De volgende kansverdeling spreekt mij aan:
A8: 7 | B8: Hoe vaak controleert u de waarde van uw portefeuille? | C8: hoe_vaak | D8: Ik controleer de waarde van mijn beleggingen:
A9: 8 | B9: Bij welke tussentijdse waardedaling van uw portefeuille maakt u zich zorgen? | C9: waardedaling | D9: Ik maak me zorgen:
A10: 9 | B10: Waaruit bestaat uw huidige beleggingsportefeuille? | C10: huidige | D10: Mijn huidige beleggingen zijn:
A11: 10 | B11: Wat is uw beleggingshorizon? (Hoelang denkt u uw beleggingen aan te houden?) | C11: horizon | D11: Mijn beleggingshorizon is:
A12: 11 | B12: Heeft u ervaring met beleggen? | C12: ervaring | D12: Ervaring met beleggen:
A13: 12 | B13: Wat is uw rendementsdoelstelling? | C13: rendementsdoelstelling | D13: Mijn rendementsdoelstelling is:

Sheet vragen_antwoorden org
A1: nummer | B1: vraag | C1: onderwerp | D1: letter | E1: antwoord_aanhef | F1: antwoord | G1: punten | H1: selected
A2: 1 | B2: =VLOOKUP(A2,'vragen org'!A:B,2,0) -> Wat is uw beleggingsdoelstelling? | C2: =VLOOKUP(A2,'vragen org'!A:C,3,0) -> beleggingsdoelstelling | D2: A | E2: =VLOOKUP(A2,'vragen org'!A:E,4,0) -> Mijn beleggingsdoelstelling is: | F2: Vermogensgroei of vermogensbehoud met een bepaald doelvermogen | G2: 2
A3: 1 | B3: =VLOOKUP(A3,'vragen org'!A:B,2,0) -> Wat is uw beleggingsdoelstelling? | C3: =VLOOKUP(A3,'vragen org'!A:C,3,0) -> beleggingsdoelstelling | D3: B | E3: =VLOOKUP(A3,'vragen org'!A:E,4,0) -> Mijn beleggingsdoelstelling is: | F3: Vermogensgroei of vermogensbehoud zonder een bepaald doelvermogen | G3: 3 | H3: =F3 -> Vermogensgroei of vermogensbehoud zonder een bepaald doelvermogen
A4: 1 | B4: =VLOOKUP(A4,'vragen org'!A:B,2,0) -> Wat is uw beleggingsdoelstelling? | C4: =VLOOKUP(A4,'vragen org'!A:C,3,0) -> beleggingsdoelstelling | D4: C | E4: =VLOOKUP(A4,'vragen org'!A:E,4,0) -> Mijn beleggingsdoelstelling is: | F4: Een jaarlijkse aanvulling op het huidige inkomen | G4: 0
A5: 1 | B5: =VLOOKUP(A5,'vragen org'!A:B,2,0) -> Wat is uw beleggingsdoelstelling? | C5: =VLOOKUP(A5,'vragen org'!A:C,3,0) -> beleggingsdoelstelling | D5: D | E5: =VLOOKUP(A5,'vragen org'!A:E,4,0) -> Mijn beleggingsdoelstelling is: | F5: De financiering van een toekomstige uitgave, bv de studie van kinderen, of eerder stoppen met werken | G5: 1
A6: 2 | B6: =VLOOKUP(A6,'vragen org'!A:B,2,0) -> Bent U van plan tussentijds vermogen aan uw beleggingsportefeuille te onttrekken of juist vervolgstortingen te doen? | C6: =VLOOKUP(A6,'vragen org'!A:C,3,0) -> bijstortingen | D6: A | E6: =VLOOKUP(A6,'vragen org'!A:E,4,0) -> Ik ben van plan: | F6: Periodiek te onttrekken | G6: 0
A7: 2 | B7: =VLOOKUP(A7,'vragen org'!A:B,2,0) -> Bent U van plan tussentijds vermogen aan uw beleggingsportefeuille te onttrekken of juist vervolgstortingen te doen? | C7: =VLOOKUP(A7,'vragen org'!A:C,3,0) -> bijstortingen | D7: B | E7: =VLOOKUP(A7,'vragen org'!A:E,4,0) -> Ik ben van plan: | F7: Periodiek bij te storten | G7: 6
A8: 2 | B8: =VLOOKUP(A8,'vragen org'!A:B,2,0) -> Bent U van plan tussentijds vermogen aan uw beleggingsportefeuille te onttrekken of juist vervolgstortingen te doen? | C8: =VLOOKUP(A8,'vragen org'!A:C,3,0) -> bijstortingen | D8: C | E8: =VLOOKUP(A8,'vragen org'!A:E,4,0) -> Ik ben van plan: | F8: Incidenteel te onttrekken | G8: 2
A9: 2 | B9: =VLOOKUP(A9,'vragen org'!A:B,2,0) -> Bent U van plan tussentijds vermogen aan uw beleggingsportefeuille te onttrekken of juist vervolgstortingen te doen? | C9: =VLOOKUP(A9,'vragen org'!A:C,3,0) -> bijstortingen | D9: D | E9: =VLOOKUP(A9,'vragen org'!A:E,4,0) -> Ik ben van plan: | F9: Incidenteel bij te storten | G9: 4
A10: 2 | B10: =VLOOKUP(A10,'vragen org'!A:B,2,0) -> Bent U van plan tussentijds vermogen aan uw beleggingsportefeuille te onttrekken of juist vervolgstortingen te doen? | C10: =VLOOKUP(A10,'vragen org'!A:C,3,0) -> bijstortingen | D10: E | E10: =VLOOKUP(A10,'vragen org'!A:E,4,0) -> Ik ben van plan: | F10: Per saldo geen bijstortingen of onttrekkingen te doen | G10: 3 | H10: =F10 -> Per saldo geen bijstortingen of onttrekkingen te doen
A11: 3 | B11: =VLOOKUP(A11,'vragen org'!A:B,2,0) -> Welke gevolgen heeft het niet halen van uw beleggingsdoelstellingen? | C11: =VLOOKUP(A11,'vragen org'!A:C,3,0) -> gevolgen | D11: A | E11: =VLOOKUP(A11,'vragen org'!A:E,4,0) -> Het niet halen van doelstellingen: | F11: Heeft noch financiële, noch emotionele gevolgen | G11: 3
A12: 3 | B12: =VLOOKUP(A12,'vragen org'!A:B,2,0) -> Welke gevolgen heeft het niet halen van uw beleggingsdoelstellingen? | C12: =VLOOKUP(A12,'vragen org'!A:C,3,0) -> gevolgen | D12: B | E12: =VLOOKUP(A12,'vragen org'!A:E,4,0) -> Het niet halen van doelstellingen: | F12: Zou grote financiële en emotionele consequenties hebben | G12: 0
A13: 3 | B13: =VLOOKUP(A13,'vragen org'!A:B,2,0) -> Welke gevolgen heeft het niet halen van uw beleggingsdoelstellingen? | C13: =VLOOKUP(A13,'vragen org'!A:C,3,0) -> gevolgen | D13: C | E13: =VLOOKUP(A13,'vragen org'!A:E,4,0) -> Het niet halen van doelstellingen: | F13: Zou teleurstellend zijn, maar nauwelijks invloed hebben op mijn levenspeil | G13: 2 | H13: =F13 -> Zou teleurstellend zijn, maar nauwelijks invloed hebben op mijn levenspeil
A14: 3 | B14: =VLOOKUP(A14,'vragen org'!A:B,2,0) -> Welke gevolgen heeft het niet halen van uw beleggingsdoelstellingen? | C14: =VLOOKUP(A14,'vragen org'!A:C,3,0) -> gevolgen | D14: D | E14: =VLOOKUP(A14,'vragen org'!A:E,4,0) -> Het niet halen van doelstellingen: | F14: Zou leiden tot aanpassing van mijn levensstandaard | G14: 1
A15: 3 | B15: =VLOOKUP(A15,'vragen org'!A:B,2,0) -> Welke gevolgen heeft het niet halen van uw beleggingsdoelstellingen? | C15: =VLOOKUP(A15,'vragen org'!A:C,3,0) -> gevolgen | D15: E | E15: =VLOOKUP(A15,'vragen org'!A:E,4,0) -> Het niet halen van doelstellingen: | F15: Dit zou gevolgen hebben voor………………………. | G15: 1
A16: 4 | B16: =VLOOKUP(A16,'vragen org'!A:B,2,0) -> Welk deel van uw vrij beschikbare vermogen (exclusief de eigen woning) is of wordt belegd op de rekening die wordt beheerd door B.A. van Doorn Comp? | C16: =VLOOKUP(A16,'vragen org'!A:C,3,0) -> deel | D16: A | E16: =VLOOKUP(A16,'vragen org'!A:E,4,0) -> Het deel van mijn vermogen dat wordt beheerd door B.A. van Doorn Comp is: | F16: Meer dan 75% | G16: 0
A17: 4 | B17: =VLOOKUP(A17,'vragen org'!A:B,2,0) -> Welk deel van uw vrij beschikbare vermogen (exclusief de eigen woning) is of wordt belegd op de rekening die wordt beheerd door B.A. van Doorn Comp? | C17: =VLOOKUP(A17,'vragen org'!A:C,3,0) -> deel | D17: B | E17: =VLOOKUP(A17,'vragen org'!A:E,4,0) -> Het deel van mijn vermogen dat wordt beheerd door B.A. van Doorn Comp is: | F17: 50% - 75% | G17: 1
A18: 4 | B18: =VLOOKUP(A18,'vragen org'!A:B,2,0) -> Welk deel van uw vrij beschikbare vermogen (exclusief de eigen woning) is of wordt belegd op de rekening die wordt beheerd door B.A. van Doorn Comp? | C18: =VLOOKUP(A18,'vragen org'!A:C,3,0) -> deel | D18: C | E18: =VLOOKUP(A18,'vragen org'!A:E,4,0) -> Het deel van mijn vermogen dat wordt beheerd door B.A. van Doorn Comp is: | F18: 25% - 50% | G18: 2 | H18: =F18 -> 25% - 50%
A19: 4 | B19: =VLOOKUP(A19,'vragen org'!A:B,2,0) -> Welk deel van uw vrij beschikbare vermogen (exclusief de eigen woning) is of wordt belegd op de rekening die wordt beheerd door B.A. van Doorn Comp? | C19: =VLOOKUP(A19,'vragen org'!A:C,3,0) -> deel | D19: D | E19: =VLOOKUP(A19,'vragen org'!A:E,4,0) -> Het deel van mijn vermogen dat wordt beheerd door B.A. van Doorn Comp is: | F19: Minder dan 25% | G19: 3
A20: 5 | B20: =VLOOKUP(A20,'vragen org'!A:B,2,0) -> Uw huidige inkomen (uit loon, pensioen onderneming ed) is : | C20: =VLOOKUP(A20,'vragen org'!A:C,3,0) -> inkomen | D20: A | E20: =VLOOKUP(A20,'vragen org'!A:E,4,0) -> Mijn huidige inkomen is: | F20: Onvoldoende om uw vaste lasten en kosten van levensonderhoud te betalen. | G20: 0
A21: 5 | B21: =VLOOKUP(A21,'vragen org'!A:B,2,0) -> Uw huidige inkomen (uit loon, pensioen onderneming ed) is : | C21: =VLOOKUP(A21,'vragen org'!A:C,3,0) -> inkomen | D21: B | E21: =VLOOKUP(A21,'vragen org'!A:E,4,0) -> Mijn huidige inkomen is: | F21: Soms voldoende, soms onvoldoende. Aan het eind van het jaar komt u ongeveer uit. | G21: 2
A22: 5 | B22: =VLOOKUP(A22,'vragen org'!A:B,2,0) -> Uw huidige inkomen (uit loon, pensioen onderneming ed) is : | C22: =VLOOKUP(A22,'vragen org'!A:C,3,0) -> inkomen | D22: C | E22: =VLOOKUP(A22,'vragen org'!A:E,4,0) -> Mijn huidige inkomen is: | F22: Voldoende om uw vaste lasten en kosten van levensonderhoud te betalen. | G22: 4 | H22: =F22 -> Voldoende om uw vaste lasten en kosten van levensonderhoud te betalen.
A23: 5 | B23: =VLOOKUP(A23,'vragen org'!A:B,2,0) -> Uw huidige inkomen (uit loon, pensioen onderneming ed) is : | C23: =VLOOKUP(A23,'vragen org'!A:C,3,0) -> inkomen | D23: D | E23: =VLOOKUP(A23,'vragen org'!A:E,4,0) -> Mijn huidige inkomen is: | F23: Ruim voldoende om uw vaste lasten en kosten van levensonderhoud te betalen. | G23: 6
A24: 5 | B24: =VLOOKUP(A24,'vragen org'!A:B,2,0) -> Uw huidige inkomen (uit loon, pensioen onderneming ed) is : | C24: =VLOOKUP(A24,'vragen org'!A:C,3,0) -> inkomen | D24: E | E24: =VLOOKUP(A24,'vragen org'!A:E,4,0) -> Mijn huidige inkomen is: | F24: Voldoende om maandelijks een aanzienlijk bedrag opzij te zetten. | G24: 8
A25: 6 | B25: =VLOOKUP(A25,'vragen org'!A:B,2,0) -> Welke kansverdeling spreekt u het meest aan voor het door U te beleggen vermogen? | C25: =VLOOKUP(A25,'vragen org'!A:C,3,0) -> kansverdeling | D25: A | E25: =VLOOKUP(A25,'vragen org'!A:E,4,0) -> De volgende kansverdeling spreekt mij aan: | F25: Een gemiddeld rendement van 6%, maar in een slecht jaar kan ik uitkomen op min 29% | G25: 3
A26: 6 | B26: =VLOOKUP(A26,'vragen org'!A:B,2,0) -> Welke kansverdeling spreekt u het meest aan voor het door U te beleggen vermogen? | C26: =VLOOKUP(A26,'vragen org'!A:C,3,0) -> kansverdeling | D26: B | E26: =VLOOKUP(A26,'vragen org'!A:E,4,0) -> De volgende kansverdeling spreekt mij aan: | F26: Een gemiddeld rendement van 3%, maar in een slecht jaar kan ik uitkomen op min 14% | G26: 2 | H26: =F26 -> Een gemiddeld rendement van 3%, maar in een slecht jaar kan ik uitkomen op min 14%
A27: 6 | B27: =VLOOKUP(A27,'vragen org'!A:B,2,0) -> Welke kansverdeling spreekt u het meest aan voor het door U te beleggen vermogen? | C27: =VLOOKUP(A27,'vragen org'!A:C,3,0) -> kansverdeling | D27: C | E27: =VLOOKUP(A27,'vragen org'!A:E,4,0) -> De volgende kansverdeling spreekt mij aan: | F27: Een gemiddeld rendement van 1%, maar in een slecht jaar kan ik uitkomen op min 8% | G27: 1
A28: 6 | B28: =VLOOKUP(A28,'vragen org'!A:B,2,0) -> Welke kansverdeling spreekt u het meest aan voor het door U te beleggen vermogen? | C28: =VLOOKUP(A28,'vragen org'!A:C,3,0) -> kansverdeling | D28: D | E28: =VLOOKUP(A28,'vragen org'!A:E,4,0) -> De volgende kansverdeling spreekt mij aan: | F28: Een jaarlijks rendement gelijk aan de spaarrente, ook in een slecht jaar. | G28: 0
A29: 7 | B29: =VLOOKUP(A29,'vragen org'!A:B,2,0) -> Hoe vaak controleert u de waarde van uw portefeuille? | C29: =VLOOKUP(A29,'vragen org'!A:C,3,0) -> hoe_vaak | D29: A | E29: =VLOOKUP(A29,'vragen org'!A:E,4,0) -> Ik controleer de waarde van mijn beleggingen: | F29: Iedere dag | G29: 0
A30: 7 | B30: =VLOOKUP(A30,'vragen org'!A:B,2,0) -> Hoe vaak controleert u de waarde van uw portefeuille? | C30: =VLOOKUP(A30,'vragen org'!A:C,3,0) -> hoe_vaak | D30: B | E30: =VLOOKUP(A30,'vragen org'!A:E,4,0) -> Ik controleer de waarde van mijn beleggingen: | F30: Iedere maand | G30: 1
A31: 7 | B31: =VLOOKUP(A31,'vragen org'!A:B,2,0) -> Hoe vaak controleert u de waarde van uw portefeuille? | C31: =VLOOKUP(A31,'vragen org'!A:C,3,0) -> hoe_vaak | D31: C | E31: =VLOOKUP(A31,'vragen org'!A:E,4,0) -> Ik controleer de waarde van mijn beleggingen: | F31: Ieder kwartaal | G31: 2 | H31: =F31 -> Ieder kwartaal
A32: 7 | B32: =VLOOKUP(A32,'vragen org'!A:B,2,0) -> Hoe vaak controleert u de waarde van uw portefeuille? | C32: =VLOOKUP(A32,'vragen org'!A:C,3,0) -> hoe_vaak | D32: D | E32: =VLOOKUP(A32,'vragen org'!A:E,4,0) -> Ik controleer de waarde van mijn beleggingen: | F32: Eens in het jaar | G32: 3
A33: 8 | B33: =VLOOKUP(A33,'vragen org'!A:B,2,0) -> Bij welke tussentijdse waardedaling van uw portefeuille maakt u zich zorgen? | C33: =VLOOKUP(A33,'vragen org'!A:C,3,0) -> waardedaling | D33: A | E33: =VLOOKUP(A33,'vragen org'!A:E,4,0) -> Ik maak me zorgen: | F33: Bij elke waardedaling, de waarde mag absoluut niet dalen | G33: 0
A34: 8 | B34: =VLOOKUP(A34,'vragen org'!A:B,2,0) -> Bij welke tussentijdse waardedaling van uw portefeuille maakt u zich zorgen? | C34: =VLOOKUP(A34,'vragen org'!A:C,3,0) -> waardedaling | D34: B | E34: =VLOOKUP(A34,'vragen org'!A:E,4,0) -> Ik maak me zorgen: | F34: Bij een waardedaling groter dan 10% | G34: 1
A35: 8 | B35: =VLOOKUP(A35,'vragen org'!A:B,2,0) -> Bij welke tussentijdse waardedaling van uw portefeuille maakt u zich zorgen? | C35: =VLOOKUP(A35,'vragen org'!A:C,3,0) -> waardedaling | D35: C | E35: =VLOOKUP(A35,'vragen org'!A:E,4,0) -> Ik maak me zorgen: | F35: Bij een waardedaling groter dan 25% | G35: 2 | H35: =F35 -> Bij een waardedaling groter dan 25%
A36: 8 | B36: =VLOOKUP(A36,'vragen org'!A:B,2,0) -> Bij welke tussentijdse waardedaling van uw portefeuille maakt u zich zorgen? | C36: =VLOOKUP(A36,'vragen org'!A:C,3,0) -> waardedaling | D36: D | E36: =VLOOKUP(A36,'vragen org'!A:E,4,0) -> Ik maak me zorgen: | F36: Dit hangt af van het negatieve rendement van de markt (index) | G36: 3
A37: 9 | B37: =VLOOKUP(A37,'vragen org'!A:B,2,0) -> Waaruit bestaat uw huidige beleggingsportefeuille? | C37: =VLOOKUP(A37,'vragen org'!A:C,3,0) -> huidige | D37: A | E37: =VLOOKUP(A37,'vragen org'!A:E,4,0) -> Mijn huidige beleggingen zijn: | F37: Alleen of nagenoeg alleen cash en spaargeld | G37: 0
A38: 9 | B38: =VLOOKUP(A38,'vragen org'!A:B,2,0) -> Waaruit bestaat uw huidige beleggingsportefeuille? | C38: =VLOOKUP(A38,'vragen org'!A:C,3,0) -> huidige | D38: B | E38: =VLOOKUP(A38,'vragen org'!A:E,4,0) -> Mijn huidige beleggingen zijn: | F38: Alleen of bijna alleen aandelen en/of derivaten | G38: 3
A39: 9 | B39: =VLOOKUP(A39,'vragen org'!A:B,2,0) -> Waaruit bestaat uw huidige beleggingsportefeuille? | C39: =VLOOKUP(A39,'vragen org'!A:C,3,0) -> huidige | D39: C | E39: =VLOOKUP(A39,'vragen org'!A:E,4,0) -> Mijn huidige beleggingen zijn: | F39: Een mengeling van aandelen, obligaties en andere beleggingen | G39: 2 | H39: =F39 -> Een mengeling van aandelen, obligaties en andere beleggingen
A40: 9 | B40: =VLOOKUP(A40,'vragen org'!A:B,2,0) -> Waaruit bestaat uw huidige beleggingsportefeuille? | C40: =VLOOKUP(A40,'vragen org'!A:C,3,0) -> huidige | D40: D | E40: =VLOOKUP(A40,'vragen org'!A:E,4,0) -> Mijn huidige beleggingen zijn: | F40: Alleen of bijna alleen obligaties en spaargeld | G40: 1
...

Sheet vragen_antwoorden_prive_nl
A1: categorie | B1: onderwerp | C1: vraag | D1: antwoord | E1: punten | F1: selected
A2: beleggingsdoelstelling | B2: beleggingsdoelstelling | C2: Ik wil mijn vermogen beleggen | D2: zodat ik hiermee binnen afzienbare tijd een uitgave kan betalen - zie ook de invulvelden hieronder | E2: 1
A3: beleggingsdoelstelling | B3: beleggingsdoelstelling | C3: Ik wil mijn vermogen beleggen | D3: om het grotendeels in stand te houden | E3: 2
A4: beleggingsdoelstelling | B4: beleggingsdoelstelling | C4: Ik wil mijn vermogen beleggen | D4: om het zonder veel neerwaarts risico te beleggen, met kans op enige groei. | E4: 3
A5: beleggingsdoelstelling | B5: beleggingsdoelstelling | C5: Ik wil mijn vermogen beleggen | D5: om het te laten groeien op de langere termijn | E5: 4 | F5: =D5 -> om het te laten groeien op de langere termijn
A6: beleggingsdoelstelling | B6: beleggingsdoelstelling | C6: Ik wil mijn vermogen beleggen | D6: om op de lange termijn kans te hebben op het hoogste resultaat | E6: 5
A7: beleggingsdoelstelling | B7: beleggingsdoelstelling_toelichting | C7: Wilt u een toelichting geven op uw beleggingsdoelstelling? | D7: nee, dat is in het antwoord op de vorige vraag voldoende verwoord | E7: 0 | F7: =D7 -> nee, dat is in het antwoord op de vorige vraag voldoende verwoord
A8: beleggingsdoelstelling | B8: beleggingsdoelstelling_toelichting | C8: Wilt u een toelichting geven op uw beleggingsdoelstelling? | D8: ja graag - hieronder opent een tekstvakje waarin u een toelichting kunt schrijven | E8: 0
A9: financiele_situatie | B9: eigen_vermogen_omvang | C9: Eigen vermogen is de waarde van uw bezittingen minus de schulden, zoals een hypotheek. Mijn eigen vermogen | D9: is niet voldoende om mijn bestedingspatroon te kunnen handhaven | E9: 1
A10: financiele_situatie | B10: eigen_vermogen_omvang | C10: Eigen vermogen is de waarde van uw bezittingen minus de schulden, zoals een hypotheek. Mijn eigen vermogen | D10: is voldoende om mijn bestedingspatroon te handhaven | E10: 2 | F10: =D10 -> is voldoende om mijn bestedingspatroon te handhaven
A11: financiele_situatie | B11: eigen_vermogen_omvang | C11: Eigen vermogen is de waarde van uw bezittingen minus de schulden, zoals een hypotheek. Mijn eigen vermogen | D11: overstijgt ruimschoots de behoefte aan reguliere uitgaven in de toekomst | E11: 3
A12: financiele_situatie | B12: eigen_vermogen_liquiditeit | C12: Het eigen vermogen kan vrij belegbaar zijn en/of belegd zijn in vastgoed of andere minder makkelijk verhandelbare vermogensbestanddelen. Mijn eigen vermogen | D12: is slechts beperkt vrij te beleggen en bestaat uit vastgoed (waaronder de eigen woning) en/of minder makkelijk verhandelbare vermogensbestanddelen | E12: 1
A13: financiele_situatie | B13: eigen_vermogen_liquiditeit | C13: Het eigen vermogen kan vrij belegbaar zijn en/of belegd zijn in vastgoed of andere minder makkelijk verhandelbare vermogensbestanddelen. Mijn eigen vermogen | D13: is grotendeels vrij te beleggen en bestaat deels uit vastgoed (waaronder de eigen woning) en/of minder makkelijk verhandelbare vermogensbestanddelen | E13: 2 | F13: =D13 -> is grotendeels vrij te beleggen en bestaat deels uit vastgoed (waaronder de eigen woning) en/of minder makkelijk verhandelbare vermogensbestanddelen
A14: financiele_situatie | B14: eigen_vermogen_liquiditeit | C14: Het eigen vermogen kan vrij belegbaar zijn en/of belegd zijn in vastgoed of andere minder makkelijk verhandelbare vermogensbestanddelen. Mijn eigen vermogen | D14: is vrij te beleggen | E14: 3
A15: financiele_situatie | B15: deel | C15: Het deel van het vrij belegbare vermogen dat ik bij B.A. van Doorn onderbreng | D15: is een kwart of minder | E15: 3
A16: financiele_situatie | B16: deel | C16: Het deel van het vrij belegbare vermogen dat ik bij B.A. van Doorn onderbreng | D16: is ongeveer de helft | E16: 2 | F16: =D16 -> is ongeveer de helft
A17: financiele_situatie | B17: deel | C17: Het deel van het vrij belegbare vermogen dat ik bij B.A. van Doorn onderbreng | D17: is meer dan de helft | E17: 1
A18: financiele_situatie | B18: inkomen | C18: Mijn inkomen (zoals uit loon, pensioen, of onderneming) | D18: is onvoldoende om van te leven en ik moet periodiek onttrekkingen doen | E18: 1
A19: financiele_situatie | B19: inkomen | C19: Mijn inkomen (zoals uit loon, pensioen, of onderneming) | D19: is genoeg om van te leven, waardoor ik slechts incidenteel onttrekkingen hoef te doen | E19: 2
A20: financiele_situatie | B20: inkomen | C20: Mijn inkomen (zoals uit loon, pensioen, of onderneming) | D20: is meer dan voldoende en ik kan mijn vermogen laten groeien, behoudens evt. onttrekkingen voor box3-belasting | E20: 3 | F20: =D20 -> is meer dan voldoende en ik kan mijn vermogen laten groeien, behoudens evt. onttrekkingen voor box3-belasting
A21: financiele_situatie | B21: gevolgen_materieel | C21: Louter financieel gezien, zonder mijn bestedingspatroon te hoeven bijstellen, | D21: kan ik maar een beperkte waardedaling van mijn beleggingen hebben | E21: 1
A22: financiele_situatie | B22: gevolgen_materieel | C22: Louter financieel gezien, zonder mijn bestedingspatroon te hoeven bijstellen, | D22: kan ik een waardedaling van mijn beleggingen aan van ongeveer 25% | E22: 2 | F22: =D22 -> kan ik een waardedaling van mijn beleggingen aan van ongeveer 25%
A23: financiele_situatie | B23: gevolgen_materieel | C23: Louter financieel gezien, zonder mijn bestedingspatroon te hoeven bijstellen, | D23: kan ik een waardedaling van mijn beleggingen aan van wel zo'n 40% | E23: 3
A24: financiele_situatie | B24: huidige_samenstelling | C24: Mijn huidige vrij belegbare vermogen (dus naast de eigen woning) | D24: bestaat overwegend uit spaargeld en/of obligaties | E24: 0
A25: financiele_situatie | B25: huidige_samenstelling | C25: Mijn huidige vrij belegbare vermogen (dus naast de eigen woning) | D25: is belegd in een portefeuille aandelen en obligaties | E25: 0 | F25: =D25 -> is belegd in een portefeuille aandelen en obligaties
A26: financiele_situatie | B26: huidige_samenstelling | C26: Mijn huidige vrij belegbare vermogen (dus naast de eigen woning) | D26: is vooral belegd in aandelen en andere risicodragende beleggingen | E26: 0
A27: kennis_ervaring | B27: kennis_beleggen | C27: Mijn kennis van beleggen | D27: is beperkt, ik weet er weinig van | E27: 1
A28: kennis_ervaring | B28: kennis_beleggen | C28: Mijn kennis van beleggen | D28: is gemiddeld en ik volg af en toe het financiële nieuws | E28: 2 | F28: =D28 -> is gemiddeld en ik volg af en toe het financiële nieuws
A29: kennis_ervaring | B29: kennis_beleggen | C29: Mijn kennis van beleggen | D29: is uitgebreid en ik volg het financiële nieuws op de voet | E29: 3
A30: kennis_ervaring | B30: kennis_instrumenten | C30: Mijn kennis van beleggingsinstrumenten | D30: is beperkt, ik weet er weinig van | E30: 1
A31: kennis_ervaring | B31: kennis_instrumenten | C31: Mijn kennis van beleggingsinstrumenten | D31: is aanwezig, ik weet wat aandelen en obligaties zijn | E31: 2 | F31: =D31 -> is aanwezig, ik weet wat aandelen en obligaties zijn
A32: kennis_ervaring | B32: kennis_instrumenten | C32: Mijn kennis van beleggingsinstrumenten | D32: is aanwezig, ik weet wat aandelen, obligaties en alternatieve beleggingen zijn | E32: 3
A33: kennis_ervaring | B33: ervaring_beleggingsdienstverlening | C33: Met beleggingsdienstverlening | D33: heb ik geen ervaring | E33: 1
A34: kennis_ervaring | B34: ervaring_beleggingsdienstverlening | C34: Met beleggingsdienstverlening | D34: heb ik ervaring, vooral met beleggingsadvies en/of execution only | E34: 3
A35: kennis_ervaring | B35: ervaring_beleggingsdienstverlening | C35: Met beleggingsdienstverlening | D35: heb ik ervaring, vooral met vermogensbeheer | E35: 2 | F35: =D35 -> heb ik ervaring, vooral met vermogensbeheer
A36: kennis_ervaring | B36: ervaring_beleggen | C36: Mijn ervaring met beleggen | D36: Ik heb geen ervaring met beleggen | E36: 1
A37: kennis_ervaring | B37: ervaring_beleggen | C37: Mijn ervaring met beleggen | D37: is beperkt | E37: 2
A38: kennis_ervaring | B38: ervaring_beleggen | C38: Mijn ervaring met beleggen | D38: is ruim aanwezig | E38: 3 | F38: =D38 -> is ruim aanwezig
A39: risicobereidheid | B39: gevolgen_emotioneel | C39: Als het gaat om slechte beleggingsresultaten | D39: daar kan ik, emotioneel gezien, niet goed tegen | E39: 1
A40: risicobereidheid | B40: gevolgen_emotioneel | C40: Als het gaat om slechte beleggingsresultaten | D40: ben ik bereid, op enig moment, ongeveer 25% waardedaling te accepteren | E40: 2 | F40: =D40 -> ben ik bereid, op enig moment, ongeveer 25% waardedaling te accepteren
...

Sheet vragen_antwoorden_prive_en
A1: categorie | B1: onderwerp | C1: vraag | D1: antwoord | E1: punten | F1: selected
A2: beleggingsdoelstelling | B2: beleggingsdoelstelling | C2: I want to invest my assets | D2: so that I can pay for an expense in the foreseeable future - see also the input fields below | E2: 1
A3: beleggingsdoelstelling | B3: beleggingsdoelstelling | C3: I want to invest my assets | D3: to preserve it for the most part | E3: 2
A4: beleggingsdoelstelling | B4: beleggingsdoelstelling | C4: I want to invest my assets | D4: to invest it without much downside risk, with the chance of some growth. | E4: 3
A5: beleggingsdoelstelling | B5: beleggingsdoelstelling | C5: I want to invest my assets | D5: to grow it in the longer term | E5: 4 | F5: to grow it in the longer term
A6: beleggingsdoelstelling | B6: beleggingsdoelstelling | C6: I want to invest my assets | D6: to have a chance of achieving the highest result in the long term | E6: 5
A7: beleggingsdoelstelling | B7: beleggingsdoelstelling_toelichting | C7: Would you like to explain your investment objective? | D7: No, that is sufficiently expressed in the answer to the previous question | E7: 0 | F7: No, that is sufficiently expressed in the answer to the previous question
A8: beleggingsdoelstelling | B8: beleggingsdoelstelling_toelichting | C8: Would you like to explain your investment objective? | D8: Yes please - below a text box opens in which you can write an explanation | E8: 0
A9: financiele_situatie | B9: eigen_vermogen_omvang | C9: Equity is the value of your assets minus debts, such as a mortgage. My equity | D9: is not enough to maintain my spending habits | E9: 1
A10: financiele_situatie | B10: eigen_vermogen_omvang | C10: Equity is the value of your assets minus debts, such as a mortgage. My equity | D10: is enough to maintain my spending habits | E10: 2 | F10: is enough to maintain my spending habits
A11: financiele_situatie | B11: eigen_vermogen_omvang | C11: Equity is the value of your assets minus debts, such as a mortgage. My equity | D11: far exceeds the need for regular spending in the future | E11: 3
A12: financiele_situatie | B12: eigen_vermogen_liquiditeit | C12: The equity can be freely investable and/or invested in real estate or other assets that are less easily tradable. My equity | D12: is only to a limited extent free to invest and consists of real estate (including the owner-occupied home) and/or less easily tradable assets | E12: 1
A13: financiele_situatie | B13: eigen_vermogen_liquiditeit | C13: The equity can be freely investable and/or invested in real estate or other assets that are less easily tradable. My equity | D13: is largely free to invest and consists partly of real estate (including the owner-occupied home) and/or less easily tradable assets | E13: 2 | F13: is largely free to invest and consists partly of real estate (including the owner-occupied home) and/or less easily tradable assets
A14: financiele_situatie | B14: eigen_vermogen_liquiditeit | C14: The equity can be freely investable and/or invested in real estate or other assets that are less easily tradable. My equity | D14: is free to invest | E14: 3
A15: financiele_situatie | B15: deel | C15: The part of the freely investable assets that I place with B.A. van Doorn | D15: is a quarter or less | E15: 3
A16: financiele_situatie | B16: deel | C16: The part of the freely investable assets that I place with B.A. van Doorn | D16: is about half | E16: 2 | F16: is about half
A17: financiele_situatie | B17: deel | C17: The part of the freely investable assets that I place with B.A. van Doorn | D17: more than half of the | E17: 1
A18: financiele_situatie | B18: inkomen | C18: My income (from salary, pension, enterprise or otherwise) | D18: is insufficient to live on and I have to make periodic withdrawals | E18: 1
A19: financiele_situatie | B19: inkomen | C19: My income (from salary, pension, enterprise or otherwise) | D19: is enough to live on, so I only have to make occasional withdrawals | E19: 2
A20: financiele_situatie | B20: inkomen | C20: My income (from salary, pension, enterprise or otherwise) | D20: is more than enough and I can grow my assets, except for possibly. Withdrawals for box 3 tax | E20: 3 | F20: is more than enough and I can grow my assets, except for possibly. Withdrawals for box 3 tax
A21: financiele_situatie | B21: gevolgen_materieel | C21: Purely financially, without having to adjust my spending habits, | D21: I can only have a limited decrease in the value of my investments | E21: 1
A22: financiele_situatie | B22: gevolgen_materieel | C22: Purely financially, without having to adjust my spending habits, | D22: I can handle a decrease in the value of my investments of about 25% | E22: 2 | F22: I can handle a decrease in the value of my investments of about 25%
A23: financiele_situatie | B23: gevolgen_materieel | C23: Purely financially, without having to adjust my spending habits, | D23: I can handle a drop in the value of my investments of up to 40% | E23: 3
A24: financiele_situatie | B24: huidige_samenstelling | C24: My current freely investable assets (i.e. in addition to my own home) | D24: consists mainly of savings and/or bonds | E24: 0
A25: financiele_situatie | B25: huidige_samenstelling | C25: My current freely investable assets (i.e. in addition to my own home) | D25: is invested in a portfolio of equities and bonds | E25: 0 | F25: is invested in a portfolio of equities and bonds
A26: financiele_situatie | B26: huidige_samenstelling | C26: My current freely investable assets (i.e. in addition to my own home) | D26: is mainly invested in shares and other risk-bearing investments | E26: 0
A27: kennis_ervaring | B27: kennis_beleggen | C27: My knowledge of investing | D27: is limited, I know little about it | E27: 1
A28: kennis_ervaring | B28: kennis_beleggen | C28: My knowledge of investing | D28: is average and I occasionally follow the financial news | E28: 2 | F28: is average and I occasionally follow the financial news
A29: kennis_ervaring | B29: kennis_beleggen | C29: My knowledge of investing | D29: is extensive and I follow the financial news closely | E29: 3
A30: kennis_ervaring | B30: kennis_instrumenten | C30: My knowledge of investment instruments | D30: is limited, I know little about it | E30: 1
A31: kennis_ervaring | B31: kennis_instrumenten | C31: My knowledge of investment instruments | D31: is present, I know what stocks and bonds are | E31: 2 | F31: is present, I know what stocks and bonds are
A32: kennis_ervaring | B32: kennis_instrumenten | C32: My knowledge of investment instruments | D32: is present, I know what stocks, bonds and alternative investments are | E32: 3
A33: kennis_ervaring | B33: ervaring_beleggingsdienstverlening | C33: With investment services | D33: I have no experience | E33: 1
A34: kennis_ervaring | B34: ervaring_beleggingsdienstverlening | C34: With investment services | D34: I have experience, especially with investment advice and/or execution only | E34: 3
A35: kennis_ervaring | B35: ervaring_beleggingsdienstverlening | C35: With investment services | D35: I have experience, especially with asset management | E35: 2 | F35: I have experience, especially with asset management
A36: kennis_ervaring | B36: ervaring_beleggen | C36: My experience with investing | D36: I have no experience with investing | E36: 1
A37: kennis_ervaring | B37: ervaring_beleggen | C37: My experience with investing | D37: is limited | E37: 2
A38: kennis_ervaring | B38: ervaring_beleggen | C38: My experience with investing | D38: is widely available | E38: 3 | F38: is widely available
A39: risicobereidheid | B39: gevolgen_emotioneel | C39: When it comes to poor investment results | D39: I can't stand that, emotionally speaking, | E39: 1
A40: risicobereidheid | B40: gevolgen_emotioneel | C40: When it comes to poor investment results | D40: am I willing, at some point, to accept about a 25% decrease in value | E40: 2 | F40: am I willing, at some point, to accept about a 25% decrease in value
...

Sheet vragen_antwoorden_enof_nl
A1: categorie | B1: onderwerp | C1: vraag | D1: antwoord | E1: punten | F1: selected
A2: beleggingsdoelstelling | B2: beleggingsdoelstelling | C2: Wij willen ons vermogen beleggen | D2: zodat wij hiermee binnen afzienbare tijd een uitgave kunnen betalen - zie ook de invulvelden hieronder | E2: 1
A3: beleggingsdoelstelling | B3: beleggingsdoelstelling | C3: Wij willen ons vermogen beleggen | D3: om het grotendeels in stand te houden | E3: 2
A4: beleggingsdoelstelling | B4: beleggingsdoelstelling | C4: Wij willen ons vermogen beleggen | D4: om het zonder veel neerwaarts risico te beleggen, met kans op enige groei. | E4: 3
A5: beleggingsdoelstelling | B5: beleggingsdoelstelling | C5: Wij willen ons vermogen beleggen | D5: om het te laten groeien op de langere termijn | E5: 4 | F5: =D5 -> om het te laten groeien op de langere termijn
A6: beleggingsdoelstelling | B6: beleggingsdoelstelling | C6: Wij willen ons vermogen beleggen | D6: om op de lange termijn kans te hebben op het hoogste resultaat | E6: 5
A7: beleggingsdoelstelling | B7: beleggingsdoelstelling_toelichting | C7: Wilt u een toelichting geven op uw beleggingsdoelstelling? | D7: nee, dat is in het antwoord op de vorige vraag voldoende verwoord | E7: 0 | F7: =D7 -> nee, dat is in het antwoord op de vorige vraag voldoende verwoord
A8: beleggingsdoelstelling | B8: beleggingsdoelstelling_toelichting | C8: Wilt u een toelichting geven op uw beleggingsdoelstelling? | D8: ja graag - hieronder opent een tekstvakje waarin u een toelichting kunt schrijven | E8: 0
A9: financiele_situatie | B9: eigen_vermogen_omvang | C9: Eigen vermogen is de waarde van uw bezittingen minus de schulden, zoals een hypotheek. Ons eigen vermogen | D9: is niet voldoende om ons bestedingspatroon te kunnen handhaven | E9: 1
A10: financiele_situatie | B10: eigen_vermogen_omvang | C10: Eigen vermogen is de waarde van uw bezittingen minus de schulden, zoals een hypotheek. Ons eigen vermogen | D10: is voldoende om ons bestedingspatroon te handhaven | E10: 2 | F10: =D10 -> is voldoende om ons bestedingspatroon te handhaven
A11: financiele_situatie | B11: eigen_vermogen_omvang | C11: Eigen vermogen is de waarde van uw bezittingen minus de schulden, zoals een hypotheek. Ons eigen vermogen | D11: overstijgt ruimschoots de behoefte aan reguliere uitgaven in de toekomst | E11: 3
A12: financiele_situatie | B12: eigen_vermogen_liquiditeit | C12: Het eigen vermogen kan vrij belegbaar zijn en/of belegd zijn in vastgoed of andere minder makkelijk verhandelbare vermogensbestanddelen. Ons eigen vermogen | D12: is slechts beperkt vrij te beleggen en bestaat uit vastgoed (waaronder de eigen woning) en/of minder makkelijk verhandelbare vermogensbestanddelen | E12: 1
A13: financiele_situatie | B13: eigen_vermogen_liquiditeit | C13: Het eigen vermogen kan vrij belegbaar zijn en/of belegd zijn in vastgoed of andere minder makkelijk verhandelbare vermogensbestanddelen. Ons eigen vermogen | D13: is grotendeels vrij te beleggen en bestaat deels uit vastgoed (waaronder de eigen woning) en/of minder makkelijk verhandelbare vermogensbestanddelen | E13: 2
A14: financiele_situatie | B14: eigen_vermogen_liquiditeit | C14: Het eigen vermogen kan vrij belegbaar zijn en/of belegd zijn in vastgoed of andere minder makkelijk verhandelbare vermogensbestanddelen. Ons eigen vermogen | D14: is vrij te beleggen | E14: 3 | F14: =D14 -> is vrij te beleggen
A15: financiele_situatie | B15: deel | C15: Het deel van ons vrij belegbare vermogen dat wij bij B.A. van Doorn onderbrengen | D15: is een kwart of minder | E15: 3
A16: financiele_situatie | B16: deel | C16: Het deel van ons vrij belegbare vermogen dat wij bij B.A. van Doorn onderbrengen | D16: is ongeveer de helft | E16: 2 | F16: =D16 -> is ongeveer de helft
A17: financiele_situatie | B17: deel | C17: Het deel van ons vrij belegbare vermogen dat wij bij B.A. van Doorn onderbrengen | D17: is meer dan de helft | E17: 1
A18: financiele_situatie | B18: inkomen | C18: Ons inkomen (zoals uit loon, pensioen, of onderneming) | D18: is onvoldoende om van te leven en wij moeten periodiek onttrekkingen doen | E18: 1
A19: financiele_situatie | B19: inkomen | C19: Ons inkomen (zoals uit loon, pensioen, of onderneming) | D19: is genoeg om van te leven, waardoor wij slechts incidenteel onttrekkingen hoeven te doen | E19: 2
A20: financiele_situatie | B20: inkomen | C20: Ons inkomen (zoals uit loon, pensioen, of onderneming) | D20: is meer dan voldoende en wij kunnen ons vermogen laten groeien, behoudens evt. onttrekkingen voor box3-belasting | E20: 3 | F20: =D20 -> is meer dan voldoende en wij kunnen ons vermogen laten groeien, behoudens evt. onttrekkingen voor box3-belasting
A21: financiele_situatie | B21: gevolgen_materieel | C21: Louter financieel gezien, zonder ons bestedingspatroon te hoeven bijstellen, | D21: kunnen wij maar een beperkte waardedaling van ons beleggingen hebben | E21: 1
A22: financiele_situatie | B22: gevolgen_materieel | C22: Louter financieel gezien, zonder ons bestedingspatroon te hoeven bijstellen, | D22: kunnen wij een waardedaling van ons beleggingen aan van ongeveer 25% | E22: 2 | F22: =D22 -> kunnen wij een waardedaling van ons beleggingen aan van ongeveer 25%
A23: financiele_situatie | B23: gevolgen_materieel | C23: Louter financieel gezien, zonder ons bestedingspatroon te hoeven bijstellen, | D23: kunnen wij een waardedaling van ons beleggingen aan van wel zo'n 40% | E23: 3
A24: financiele_situatie | B24: huidige_samenstelling | C24: Ons huidige vrij belegbare vermogen (dus naast de eigen woning) | D24: bestaat overwegend uit spaargeld en/of obligaties | E24: 0
A25: financiele_situatie | B25: huidige_samenstelling | C25: Ons huidige vrij belegbare vermogen (dus naast de eigen woning) | D25: is belegd in een portefeuille aandelen en obligaties | E25: 0 | F25: =D25 -> is belegd in een portefeuille aandelen en obligaties
A26: financiele_situatie | B26: huidige_samenstelling | C26: Ons huidige vrij belegbare vermogen (dus naast de eigen woning) | D26: is vooral belegd in aandelen en andere risicodragende beleggingen | E26: 0
A27: kennis_ervaring | B27: kennis_beleggen | C27: Onze kennis van beleggen | D27: is beperkt, wij weten er weinig van | E27: 1
A28: kennis_ervaring | B28: kennis_beleggen | C28: Onze kennis van beleggen | D28: is gemiddeld en wij volgen af en toe het financiële nieuws | E28: 2 | F28: =D28 -> is gemiddeld en wij volgen af en toe het financiële nieuws
A29: kennis_ervaring | B29: kennis_beleggen | C29: Onze kennis van beleggen | D29: is uitgebreid en ik volg het financiële nieuws op de voet | E29: 3
A30: kennis_ervaring | B30: kennis_instrumenten | C30: Onze kennis van beleggingsinstrumenten | D30: is beperkt, wij weten er weinig van | E30: 1
A31: kennis_ervaring | B31: kennis_instrumenten | C31: Onze kennis van beleggingsinstrumenten | D31: is aanwezig, wij weten wat aandelen en obligaties zijn | E31: 2 | F31: =D31 -> is aanwezig, wij weten wat aandelen en obligaties zijn
A32: kennis_ervaring | B32: kennis_instrumenten | C32: Onze kennis van beleggingsinstrumenten | D32: is aanwezig, wij weten wat aandelen, obligaties en alternatieve beleggingen zijn | E32: 3
A33: kennis_ervaring | B33: ervaring_beleggingsdienstverlening | C33: Met beleggingsdienstverlening | D33: hebben wij geen ervaring | E33: 1
A34: kennis_ervaring | B34: ervaring_beleggingsdienstverlening | C34: Met beleggingsdienstverlening | D34: hebben wij ervaring, vooral met beleggingsadvies en/of execution only | E34: 3 | F34: =D34 -> hebben wij ervaring, vooral met beleggingsadvies en/of execution only
A35: kennis_ervaring | B35: ervaring_beleggingsdienstverlening | C35: Met beleggingsdienstverlening | D35: hebben wij ervaring, vooral met vermogensbeheer | E35: 2
A36: kennis_ervaring | B36: ervaring_beleggen | C36: Onze ervaring met beleggen | D36: Wij hebben geen ervaring met beleggen | E36: 1
A37: kennis_ervaring | B37: ervaring_beleggen | C37: Onze ervaring met beleggen | D37: is beperkt | E37: 2 | F37: =D37 -> is beperkt
A38: kennis_ervaring | B38: ervaring_beleggen | C38: Onze ervaring met beleggen | D38: is ruim aanwezig | E38: 3
A39: risicobereidheid | B39: gevolgen_emotioneel | C39: Als het gaat om slechte beleggingsresultaten | D39: daar kunnen wij, emotioneel gezien, niet goed tegen | E39: 1
A40: risicobereidheid | B40: gevolgen_emotioneel | C40: Als het gaat om slechte beleggingsresultaten | D40: zijn wij bereid, op enig moment, ongeveer 25% waardedaling te accepteren | E40: 2 | F40: =D40 -> zijn wij bereid, op enig moment, ongeveer 25% waardedaling te accepteren
...

Sheet vragen_antwoorden_enof_en
A1: categorie | B1: onderwerp | C1: vraag | D1: antwoord | E1: punten | F1: selected
A2: beleggingsdoelstelling | B2: beleggingsdoelstelling | C2: We want to invest our assets | D2: so that we can use it to pay for an expense in the foreseeable future - see also the input fields below | E2: 1
A3: beleggingsdoelstelling | B3: beleggingsdoelstelling | C3: We want to invest our assets | D3: to preserve it for the most part | E3: 2
A4: beleggingsdoelstelling | B4: beleggingsdoelstelling | C4: We want to invest our assets | D4: to invest it without much downside risk, with the chance of some growth. | E4: 3
A5: beleggingsdoelstelling | B5: beleggingsdoelstelling | C5: We want to invest our assets | D5: to grow it in the longer term | E5: 4 | F5: to grow it in the longer term
A6: beleggingsdoelstelling | B6: beleggingsdoelstelling | C6: We want to invest our assets | D6: to have a chance of achieving the highest result in the long term | E6: 5
A7: beleggingsdoelstelling | B7: beleggingsdoelstelling_toelichting | C7: Would you like to explain your investment objective? | D7: No, that is sufficiently expressed in the answer to the previous question | E7: 0 | F7: No, that is sufficiently expressed in the answer to the previous question
A8: beleggingsdoelstelling | B8: beleggingsdoelstelling_toelichting | C8: Would you like to explain your investment objective? | D8: Yes please - below a text box opens in which you can write an explanation | E8: 0
A9: financiele_situatie | B9: eigen_vermogen_omvang | C9: Equity is the value of your assets minus debts, such as a mortgage. Our equity | D9: is not enough to maintain our spending pattern | E9: 1
A10: financiele_situatie | B10: eigen_vermogen_omvang | C10: Equity is the value of your assets minus debts, such as a mortgage. Our equity | D10: is sufficient to maintain our spending pattern | E10: 2 | F10: is sufficient to maintain our spending pattern
A11: financiele_situatie | B11: eigen_vermogen_omvang | C11: Equity is the value of your assets minus debts, such as a mortgage. Our equity | D11: far exceeds the need for regular spending in the future | E11: 3
A12: financiele_situatie | B12: eigen_vermogen_liquiditeit | C12: The equity can be freely investable and/or invested in real estate or other assets that are less easily tradable. Our equity | D12: is only to a limited extent free to invest and consists of real estate (including the owner-occupied home) and/or less easily tradable assets | E12: 1
A13: financiele_situatie | B13: eigen_vermogen_liquiditeit | C13: The equity can be freely investable and/or invested in real estate or other assets that are less easily tradable. Our equity | D13: is largely free to invest and consists partly of real estate (including the owner-occupied home) and/or less easily tradable assets | E13: 2
A14: financiele_situatie | B14: eigen_vermogen_liquiditeit | C14: The equity can be freely investable and/or invested in real estate or other assets that are less easily tradable. Our equity | D14: is free to invest | E14: 3 | F14: is free to invest
A15: financiele_situatie | B15: deel | C15: The part of our freely investable assets that we place with B.A. van Doorn | D15: is a quarter or less | E15: 3
A16: financiele_situatie | B16: deel | C16: The part of our freely investable assets that we place with B.A. van Doorn | D16: is about half | E16: 2 | F16: is about half
A17: financiele_situatie | B17: deel | C17: The part of our freely investable assets that we place with B.A. van Doorn | D17: more than half of the | E17: 1
A18: financiele_situatie | B18: inkomen | C18: Our income (such as from wages, pensions, or businesses) | D18: is insufficient to live on and we have to make periodic withdrawals | E18: 1
A19: financiele_situatie | B19: inkomen | C19: Our income (such as from wages, pensions, or businesses) | D19: is enough to live on, so that we only have to make occasional withdrawals | E19: 2
A20: financiele_situatie | B20: inkomen | C20: Our income (such as from wages, pensions, or businesses) | D20: is more than sufficient and we can grow our assets, except for possibly. Withdrawals for box 3 tax | E20: 3 | F20: is more than sufficient and we can grow our assets, except for possibly. Withdrawals for box 3 tax
A21: financiele_situatie | B21: gevolgen_materieel | C21: From a purely financial point of view, without having to adjust our spending habits, | D21: we can only have a limited decrease in the value of our investments | E21: 1
A22: financiele_situatie | B22: gevolgen_materieel | C22: From a purely financial point of view, without having to adjust our spending habits, | D22: we can handle a decrease in the value of our investments of about 25% | E22: 2 | F22: we can handle a decrease in the value of our investments of about 25%
A23: financiele_situatie | B23: gevolgen_materieel | C23: From a purely financial point of view, without having to adjust our spending habits, | D23: we can handle a drop in the value of our investments of up to 40% | E23: 3
A24: financiele_situatie | B24: huidige_samenstelling | C24: Our current freely investable assets (i.e. in addition to our own home) | D24: consists mainly of savings and/or bonds | E24: 0
A25: financiele_situatie | B25: huidige_samenstelling | C25: Our current freely investable assets (i.e. in addition to our own home) | D25: is invested in a portfolio of equities and bonds | E25: 0 | F25: is invested in a portfolio of equities and bonds
A26: financiele_situatie | B26: huidige_samenstelling | C26: Our current freely investable assets (i.e. in addition to our own home) | D26: is mainly invested in shares and other risk-bearing investments | E26: 0
A27: kennis_ervaring | B27: kennis_beleggen | C27: Our knowledge of investing | D27: is limited, we know little about it | E27: 1
A28: kennis_ervaring | B28: kennis_beleggen | C28: Our knowledge of investing | D28: is average and we occasionally follow the financial news | E28: 2 | F28: is average and we occasionally follow the financial news
A29: kennis_ervaring | B29: kennis_beleggen | C29: Our knowledge of investing | D29: is extensive and I follow the financial news closely | E29: 3
A30: kennis_ervaring | B30: kennis_instrumenten | C30: Our knowledge of investment instruments | D30: is limited, we know little about it | E30: 1
A31: kennis_ervaring | B31: kennis_instrumenten | C31: Our knowledge of investment instruments | D31: is present, we know what stocks and bonds are | E31: 2 | F31: is present, we know what stocks and bonds are
A32: kennis_ervaring | B32: kennis_instrumenten | C32: Our knowledge of investment instruments | D32: is present, we know what shares, bonds and alternative investments are | E32: 3
A33: kennis_ervaring | B33: ervaring_beleggingsdienstverlening | C33: With investment services | D33: we have no experience | E33: 1
A34: kennis_ervaring | B34: ervaring_beleggingsdienstverlening | C34: With investment services | D34: we have experience, especially with investment advice and/or execution only | E34: 3 | F34: we have experience, especially with investment advice and/or execution only
A35: kennis_ervaring | B35: ervaring_beleggingsdienstverlening | C35: With investment services | D35: we have experience, especially with asset management | E35: 2
A36: kennis_ervaring | B36: ervaring_beleggen | C36: Our experience with investing | D36: We have no experience with investing | E36: 1
A37: kennis_ervaring | B37: ervaring_beleggen | C37: Our experience with investing | D37: is limited | E37: 2 | F37: is limited
A38: kennis_ervaring | B38: ervaring_beleggen | C38: Our experience with investing | D38: is widely available | E38: 3
A39: risicobereidheid | B39: gevolgen_emotioneel | C39: When it comes to poor investment results | D39: Emotionally, we can't handle that very well | E39: 1
A40: risicobereidheid | B40: gevolgen_emotioneel | C40: When it comes to poor investment results | D40: we are prepared, at any time, to accept about 25% decrease in value | E40: 2 | F40: we are prepared, at any time, to accept about 25% decrease in value
...

Sheet vragen_antwoorden_bv_nl
A1: categorie | B1: onderwerp | C1: vraag | D1: antwoord | E1: punten | F1: selected
A2: beleggingsdoelstelling | B2: beleggingsdoelstelling | C2: Het vermogen in de besloten vennootschap wordt belegd | D2: om hiermee binnen afzienbare tijd een uitgave te doen | E2: 1
A3: beleggingsdoelstelling | B3: beleggingsdoelstelling | C3: Het vermogen in de besloten vennootschap wordt belegd | D3: om het grotendeels in stand te houden | E3: 2
A4: beleggingsdoelstelling | B4: beleggingsdoelstelling | C4: Het vermogen in de besloten vennootschap wordt belegd | D4: om het zonder veel neerwaarts risico te beleggen, met kans op enige groei | E4: 3
A5: beleggingsdoelstelling | B5: beleggingsdoelstelling | C5: Het vermogen in de besloten vennootschap wordt belegd | D5: om het te laten groeien op de langere termijn | E5: 4 | F5: =D5 -> om het te laten groeien op de langere termijn
A6: beleggingsdoelstelling | B6: beleggingsdoelstelling | C6: Het vermogen in de besloten vennootschap wordt belegd | D6: om op de lange termijn kans te hebben op het hoogste resultaat | E6: 5
A7: beleggingsdoelstelling | B7: beleggingsdoelstelling_toelichting | C7: Wilt u een toelichting geven op de beleggingsdoelstelling van de besloten vennootschap? | D7: nee, dat is in het antwoord op de vorige vraag voldoende verwoord | E7: 0 | F7: =D7 -> nee, dat is in het antwoord op de vorige vraag voldoende verwoord
A8: beleggingsdoelstelling | B8: beleggingsdoelstelling_toelichting | C8: Wilt u een toelichting geven op de beleggingsdoelstelling van de besloten vennootschap? | D8: ja graag - hieronder opent een tekstvakje waarin u een toelichting kunt schrijven | E8: 0
A9: financiele_situatie | B9: eigen_vermogen_liquiditeit | C9: Het vermogen in de besloten vennootschap | D9: is slechts beperkt vrij te beleggen en bestaat uit verstrekte leningen, vastgoed en/of andere minder makkelijk verhandelbare vermogensbestanddelen | E9: 1
A10: financiele_situatie | B10: eigen_vermogen_liquiditeit | C10: Het vermogen in de besloten vennootschap | D10: is grotendeels vrij te beleggen en bestaat deels uit vastgoed en/of minder makkelijk verhandelbare vermogensbestanddelen | E10: 2 | F10: =D10 -> is grotendeels vrij te beleggen en bestaat deels uit vastgoed en/of minder makkelijk verhandelbare vermogensbestanddelen
A11: financiele_situatie | B11: eigen_vermogen_liquiditeit | C11: Het vermogen in de besloten vennootschap | D11: is vrij te beleggen | E11: 3
A12: financiele_situatie | B12: deel | C12: Het deel van het vrij belegbare vermogen van de besloten vennootschap dat bij B.A. van Doorn in beheer komt | D12: is een kwart of minder | E12: 3
